Workbook

Sheet Costos
A1: COSTOS Y PRECIOS
A2: Completá solo las celdas amarillas. El resto se calcula solo.
A4: 1. PACKAGING
A5: Componente | B5: Precio del pack | C5: Unidades | D5: Costo por pieza | E5: Descripción del pedido | F5: Notas
A6: Sticker isotipo | B6: 18000 | C6: 330 | D6: =IFERROR(B6/C6,0) -> 54.545455 | E6: Ideas Argentinas. Redondo 3,5 cm, fondo chocolate con la O manteca, papel adhesivo, troquelado incluido. 1 plancha de 29x40 cm = $1.600 + IVA. Producción normal 48/72 hs. Falta que confirmen cuántos entran por plancha (estimado 70, con 3 mm entre siluetas). | F6: fijarme el color para pagarle a roxana e imprimir
A7: Etiqueta interior | B7: 3450 | C7: 60 | D7: =IFERROR(B7/C7,0) -> 57.5 | E7: Ideas Argentinas. Tarjeta 8x5 cm horizontal, ilustración 300 gr, frente y dorso. Frente con logo, dorso manteca liso. Entran 30 por hoja A3+ (31x46 cm). 2 impresiones = $2.300 + IVA = 60 tarjetas. Mitad plata 925, mitad acero blanco. | F7: tengo que ir a retirar a larralde
A8: Papel seda | B8: 1600 | C8: 10 | D8: =IFERROR(B8/C8,0) -> 160 | F8: fijarme si sirven las tarjetas interiores
A9: Caja Kraft | B9: 18718 | C9: 30 | D9: =IFERROR(B9/C9,0) -> 623.93333 | F9: compre en smartpackaging, me queda retirarlo x ramallo
A10: Sticker cerrar bolsa | B10: 18000 | C10: 130 | D10: =IFERROR(B10/C10,0) -> 138.46154 | F10: mande a studioimage falta q contesten
A11: Bolsa autoadhesiva | B11: 3220 | C11: 100 | D11: =IFERROR(B11/C11,0) -> 32.2 | E11: Bolsa autoadhesiva 6x11 | F11: compre por ML tengo que retirarlo
A12: Bolsa con manija | B12: 25000 | C12: 100 | D12: =IFERROR(B12/C12,0) -> 250 | E12: Bolsa de papel con manija para entregas en mano. Sin cotizar todavía.
A13: TOTAL PACKAGING POR PIEZA | D13: =SUM(D6:D12) -> 1316.6403
A17: 2. MIS REGLAS
A18: Multiplico el costo por | B18: 2 | C18: El precio sugerido es el doble del costo total (joya + packaging).
A19: Comisión de la venta | B19: 0 | C19: Poné 0% si cobrás por transferencia.
A21: 3. PRODUCTOS
A22: Producto | B22: Material | C22: Categoría | D22: Proveedor | E22: Link de la publicación | F22: Costo de compra | G22: Descuento | H22: Packaging | I22: Costo total | J22: Precio sugerido | K22: Precio de venta | L22: Ganancia por unidad | M22: Margen
A23: Argollitas Classic N°1 | B23: Plata 925 | C23: Aros | D23: Docha | E23: Cubano N°0 | F23: 2845 | G23: 0.1 | H23: =IF($A23="","",$D$13) -> 1316.6403 | I23: =IF($A23="","",N(F23)*(1-N(G23))+N(H23)) -> 3877.1403 | J23: =IF($A23="","",CEILING(I23*$B$18,500)) -> 8000 | K23: 7000 | L23: =IF(OR($A23="",N(K23)=0),"",K23-K23*$B$19-N(I23)) -> 3122.8597 | M23: =IF(OR($A23="",N(K23)=0),"",N(L23)/K23) -> 0.44612281 | N23: ← ejemplos, pisalos con tus productos
A24: Argollitas Classic N°2 | B24: Plata 925 | C24: Aros | D24: Docha | E24: Cubano N°1 | F24: 3405 | G24: 0.1 | H24: =IF($A24="","",$D$13) -> 1316.6403 | I24: =IF($A24="","",N(F24)*(1-N(G24))+N(H24)) -> 4381.1403 | J24: =IF($A24="","",CEILING(I24*$B$18,500)) -> 9000 | K24: 7500 | L24: =IF(OR($A24="",N(K24)=0),"",K24-K24*$B$19-N(I24)) -> 3118.8597 | M24: =IF(OR($A24="",N(K24)=0),"",N(L24)/K24) -> 0.41584796
A25: Argollitas Classic N°3 | B25: Plata 925 | C25: Aros | D25: Docha | E25: Cubano N°2 | F25: 3965 | G25: 0.1 | H25: =IF($A25="","",$D$13) -> 1316.6403 | I25: =IF($A25="","",N(F25)*(1-N(G25))+N(H25)) -> 4885.1403 | J25: =IF($A25="","",CEILING(I25*$B$18,500)) -> 10000 | K25: 8000 | L25: =IF(OR($A25="",N(K25)=0),"",K25-K25*$B$19-N(I25)) -> 3114.8597 | M25: =IF(OR($A25="",N(K25)=0),"",N(L25)/K25) -> 0.38935746
A26: Argollitas Classic N°4 | B26: Plata 925 | C26: Aros | D26: Docha | E26: Cubano N°3 | F26: 4525 | G26: 0.1 | H26: =IF($A26="","",$D$13) -> 1316.6403 | I26: =IF($A26="","",N(F26)*(1-N(G26))+N(H26)) -> 5389.1403 | J26: =IF($A26="","",CEILING(I26*$B$18,500)) -> 11000 | K26: 8500 | L26: =IF(OR($A26="",N(K26)=0),"",K26-K26*$B$19-N(I26)) -> 3110.8597 | M26: =IF(OR($A26="",N(K26)=0),"",N(L26)/K26) -> 0.36598349
A27: Argollitas Classic N°5 | B27: Plata 925 | C27: Aros | D27: Docha | E27: Cubano N°4 | F27: 4805 | G27: 0.1 | H27: =IF($A27="","",$D$13) -> 1316.6403 | I27: =IF($A27="","",N(F27)*(1-N(G27))+N(H27)) -> 5641.1403 | J27: =IF($A27="","",CEILING(I27*$B$18,500)) -> 11500 | K27: 9000 | L27: =IF(OR($A27="",N(K27)=0),"",K27-K27*$B$19-N(I27)) -> 3358.8597 | M27: =IF(OR($A27="",N(K27)=0),"",N(L27)/K27) -> 0.37320663
A28: Cubic Mini Circulo | B28: Plata 925 | C28: Aros | D28: Docha | E28: Mini susanita 2mm | F28: 6400 | G28: 0.1 | H28: =IF($A28="","",$D$13) -> 1316.6403 | I28: =IF($A28="","",N(F28)*(1-N(G28))+N(H28)) -> 7076.6403 | J28: =IF($A28="","",CEILING(I28*$B$18,500)) -> 14500 | K28: 12000 | L28: =IF(OR($A28="",N(K28)=0),"",K28-K28*$B$19-N(I28)) -> 4923.3597 | M28: =IF(OR($A28="",N(K28)=0),"",N(L28)/K28) -> 0.41027997
A29: Cubic Circulo Docha | B29: Plata 925 | C29: Aros | D29: Docha | E29: Mini susanita 3mm | F29: 6800 | G29: 0.1 | H29: =IF($A29="","",$D$13) -> 1316.6403 | I29: =IF($A29="","",N(F29)*(1-N(G29))+N(H29)) -> 7436.6403 | J29: =IF($A29="","",CEILING(I29*$B$18,500)) -> 15000 | K29: 12500 | L29: =IF(OR($A29="",N(K29)=0),"",K29-K29*$B$19-N(I29)) -> 5063.3597 | M29: =IF(OR($A29="",N(K29)=0),"",N(L29)/K29) -> 0.40506877
A30: Cubic Cuadrado | B30: Plata 925 | C30: Aros | D30: Docha | E30: Cuadrado cubic 4mm | F30: 6270 | G30: 0.1 | H30: =IF($A30="","",$D$13) -> 1316.6403 | I30: =IF($A30="","",N(F30)*(1-N(G30))+N(H30)) -> 6959.6403 | J30: =IF($A30="","",CEILING(I30*$B$18,500)) -> 14000 | K30: 12500 | L30: =IF(OR($A30="",N(K30)=0),"",K30-K30*$B$19-N(I30)) -> 5540.3597 | M30: =IF(OR($A30="",N(K30)=0),"",N(L30)/K30) -> 0.44322877
A31: Argollitas Marco Docha | B31: Plata 925 | C31: Aros | D31: Docha | E31: - | F31: 18645 | G31: 0.1 | H31: =IF($A31="","",$D$13) -> 1316.6403 | I31: =IF($A31="","",N(F31)*(1-N(G31))+N(H31)) -> 18097.14 | J31: =IF($A31="","",CEILING(I31*$B$18,500)) -> 36500 | K31: 25000 | L31: =IF(OR($A31="",N(K31)=0),"",K31-K31*$B$19-N(I31)) -> 6902.8597 | M31: =IF(OR($A31="",N(K31)=0),"",N(L31)/K31) -> 0.27611439
A32: Anillo Circulo | B32: Plata 925 | C32: Anillo | D32: Docha | E32: Anillo circulo | F32: 8250 | G32: 0.1 | H32: =IF($A32="","",$D$13) -> 1316.6403 | I32: =IF($A32="","",N(F32)*(1-N(G32))+N(H32)) -> 8741.6403 | J32: =IF($A32="","",CEILING(I32*$B$18,500)) -> 17500 | K32: 16000 | L32: =IF(OR($A32="",N(K32)=0),"",K32-K32*$B$19-N(I32)) -> 7258.3597 | M32: =IF(OR($A32="",N(K32)=0),"",N(L32)/K32) -> 0.45364748
A33: Anillo Gota | B33: Plata 925 | C33: Anillo | D33: Docha | E33: - | F33: 14148 | G33: 0.1 | H33: =IF($A33="","",$D$13) -> 1316.6403 | I33: =IF($A33="","",N(F33)*(1-N(G33))+N(H33)) -> 14049.84 | J33: =IF($A33="","",CEILING(I33*$B$18,500)) -> 28500 | K33: 23000 | L33: =IF(OR($A33="",N(K33)=0),"",K33-K33*$B$19-N(I33)) -> 8950.1597 | M33: =IF(OR($A33="",N(K33)=0),"",N(L33)/K33) -> 0.38913738
A34: Anillo Vera Docha | B34: Plata 925 | C34: Anillo | D34: Docha | E34: Anillo V | F34: 6500 | G34: 0.1 | H34: =IF($A34="","",$D$13) -> 1316.6403 | I34: =IF($A34="","",N(F34)*(1-N(G34))+N(H34)) -> 7166.6403 | J34: =IF($A34="","",CEILING(I34*$B$18,500)) -> 14500 | K34: 13000 | L34: =IF(OR($A34="",N(K34)=0),"",K34-K34*$B$19-N(I34)) -> 5833.3597 | M34: =IF(OR($A34="",N(K34)=0),"",N(L34)/K34) -> 0.44871997
A35: Anillo Calado | B35: Plata 925 | C35: Anillo | D35: Docha | E35: Anillo calado | F35: 10890 | G35: 0.1 | H35: =IF($A35="","",$D$13) -> 1316.6403 | I35: =IF($A35="","",N(F35)*(1-N(G35))+N(H35)) -> 11117.64 | J35: =IF($A35="","",CEILING(I35*$B$18,500)) -> 22500 | K35: 19000 | L35: =IF(OR($A35="",N(K35)=0),"",K35-K35*$B$19-N(I35)) -> 7882.3597 | M35: =IF(OR($A35="",N(K35)=0),"",N(L35)/K35) -> 0.41486104
A36: Cadena eslabon | B36: Acero blanco | C36: Collar | D36: Docha | E36: https://dochajoyaspormayor.com.ar/tienda/john-caladito/ | F36: 3900 | G36: 0.1 | H36: =IF($A36="","",$D$13) -> 1316.6403 | I36: =IF($A36="","",N(F36)*(1-N(G36))+N(H36)) -> 4826.6403 | J36: =IF($A36="","",CEILING(I36*$B$18,500)) -> 10000 | K36: 8500 | L36: =IF(OR($A36="",N(K36)=0),"",K36-K36*$B$19-N(I36)) -> 3673.3597 | M36: =IF(OR($A36="",N(K36)=0),"",N(L36)/K36) -> 0.43215996
A37: Cadena lisa | B37: Acero blanco | C37: Collar | D37: Docha | F37: 2700 | G37: 0.1 | H37: =IF($A37="","",$D$13) -> 1316.6403 | I37: =IF($A37="","",N(F37)*(1-N(G37))+N(H37)) -> 3746.6403 | J37: =IF($A37="","",CEILING(I37*$B$18,500)) -> 7500 | K37: 7000 | L37: =IF(OR($A37="",N(K37)=0),"",K37-K37*$B$19-N(I37)) -> 3253.3597 | M37: =IF(OR($A37="",N(K37)=0),"",N(L37)/K37) -> 0.46476567
A38: Argollitas gota | B38: Acero blanco | C38: Aros | D38: Docha | F38: 3100 | G38: 0.1 | H38: =IF($A38="","",$D$13) -> 1316.6403 | I38: =IF($A38="","",N(F38)*(1-N(G38))+N(H38)) -> 4106.6403 | J38: =IF($A38="","",CEILING(I38*$B$18,500)) -> 8500 | K38: 7500 | L38: =IF(OR($A38="",N(K38)=0),"",K38-K38*$B$19-N(I38)) -> 3393.3597 | M38: =IF(OR($A38="",N(K38)=0),"",N(L38)/K38) -> 0.45244796
A39: Argollitas Caviar circulo | B39: Acero blanco | C39: Aros | D39: Docha | E39: https://dochajoyaspormayor.com.ar/tienda/click-bolitas/ | F39: 2300 | G39: 0.1 | H39: =IF($A39="","",$D$13) -> 1316.6403 | I39: =IF($A39="","",N(F39)*(1-N(G39))+N(H39)) -> 3386.6403 | J39: =IF($A39="","",CEILING(I39*$B$18,500)) -> 7000 | K39: 6500 | L39: =IF(OR($A39="",N(K39)=0),"",K39-K39*$B$19-N(I39)) -> 3113.3597 | M39: =IF(OR($A39="",N(K39)=0),"",N(L39)/K39) -> 0.47897841
A40: Argollitas Caviar triangulo | B40: Acero blanco | C40: Aros | D40: Docha | E40: https://dochajoyaspormayor.com.ar/tienda/bolitas-en-v/ | F40: 2300 | G40: 0.1 | H40: =IF($A40="","",$D$13) -> 1316.6403 | I40: =IF($A40="","",N(F40)*(1-N(G40))+N(H40)) -> 3386.6403 | J40: =IF($A40="","",CEILING(I40*$B$18,500)) -> 7000 | K40: 6500 | L40: =IF(OR($A40="",N(K40)=0),"",K40-K40*$B$19-N(I40)) -> 3113.3597 | M40: =IF(OR($A40="",N(K40)=0),"",N(L40)/K40) -> 0.47897841
A41: Argollitas Ocampo | B41: Acero blanco | C41: Aros | D41: Docha | E41: https://dochajoyaspormayor.com.ar/tienda/bolitas-en-v/ | F41: 3900 | G41: 0.1 | H41: =IF($A41="","",$D$13) -> 1316.6403 | I41: =IF($A41="","",N(F41)*(1-N(G41))+N(H41)) -> 4826.6403 | J41: =IF($A41="","",CEILING(I41*$B$18,500)) -> 10000 | K41: 7000 | L41: =IF(OR($A41="",N(K41)=0),"",K41-K41*$B$19-N(I41)) -> 2173.3597 | M41: =IF(OR($A41="",N(K41)=0),"",N(L41)/K41) -> 0.31047995
A42: Argollitas Bubble | B42: Acero blanco | C42: Aros | D42: Docha | F42: 3100 | G42: 0.1 | H42: =IF($A42="","",$D$13) -> 1316.6403 | I42: =IF($A42="","",N(F42)*(1-N(G42))+N(H42)) -> 4106.6403 | J42: =IF($A42="","",CEILING(I42*$B$18,500)) -> 8500 | K42: 6500 | L42: =IF(OR($A42="",N(K42)=0),"",K42-K42*$B$19-N(I42)) -> 2393.3597 | M42: =IF(OR($A42="",N(K42)=0),"",N(L42)/K42) -> 0.36820918
A43: Argollitas Bombe | B43: Acero blanco | C43: Aros | D43: Docha | E43: https://dochajoyaspormayor.com.ar/tienda/en-v-bombe/ | F43: 2600 | G43: 0.1 | H43: =IF($A43="","",$D$13) -> 1316.6403 | I43: =IF($A43="","",N(F43)*(1-N(G43))+N(H43)) -> 3656.6403 | J43: =IF($A43="","",CEILING(I43*$B$18,500)) -> 7500 | K43: 6500 | L43: =IF(OR($A43="",N(K43)=0),"",K43-K43*$B$19-N(I43)) -> 2843.3597 | M43: =IF(OR($A43="",N(K43)=0),"",N(L43)/K43) -> 0.43743995
A44: Argollita Duna N°0 | B44: Acero blanco | C44: Aros | D44: Docha | E44: https://dochajoyaspormayor.com.ar/tienda/carterita-snail/ | F44: 2200 | G44: 0.1 | H44: =IF($A44="","",$D$13) -> 1316.6403 | I44: =IF($A44="","",N(F44)*(1-N(G44))+N(H44)) -> 3296.6403 | J44: =IF($A44="","",CEILING(I44*$B$18,500)) -> 7000 | K44: 6500 | L44: =IF(OR($A44="",N(K44)=0),"",K44-K44*$B$19-N(I44)) -> 3203.3597 | M44: =IF(OR($A44="",N(K44)=0),"",N(L44)/K44) -> 0.49282457
A45: Argollita Duna N°1 | B45: Acero blanco | C45: Aros | D45: Docha | E45: https://dochajoyaspormayor.com.ar/tienda/carteritas-torce/ | F45: 2200 | G45: 0.1 | H45: =IF($A45="","",$D$13) -> 1316.6403 | I45: =IF($A45="","",N(F45)*(1-N(G45))+N(H45)) -> 3296.6403 | J45: =IF($A45="","",CEILING(I45*$B$18,500)) -> 7000 | K45: 6500 | L45: =IF(OR($A45="",N(K45)=0),"",K45-K45*$B$19-N(I45)) -> 3203.3597 | M45: =IF(OR($A45="",N(K45)=0),"",N(L45)/K45) -> 0.49282457
...

Sheet Compras
A1: COMPRAS
A2: Una línea por cada pieza que comprás. Elegí el producto de la lista y poné el talle solo si es anillo.
A3: Dejá el costo vacío para que tome el costo total de la hoja Costos. Escribilo solo si pagaste otro precio.
A5: Fecha | B5: Producto | C5: Talle | D5: Cantidad | E5: Costo unitario | F5: Total | G5: Proveedor / Notas
A6: 46244 | B6: Argollitas Classic N°1 | C6: Único | D6: 1 | F6: =IF($B6="","",N($D6)*IF(N($E6)>0,$E6,IFERROR(INDEX(Costos!$I$23:$I$300,MATCH($B6,Costos!$A$23:$A$300,0)),0))) -> 3877.1403 | G6: Stock inicial
A7: 46244 | B7: Argollitas Classic N°2 | C7: Único | D7: 1 | F7: =IF($B7="","",N($D7)*IF(N($E7)>0,$E7,IFERROR(INDEX(Costos!$I$23:$I$300,MATCH($B7,Costos!$A$23:$A$300,0)),0))) -> 4381.1403 | G7: Stock inicial
A8: 46244 | B8: Argollitas Classic N°3 | C8: Único | D8: 1 | F8: =IF($B8="","",N($D8)*IF(N($E8)>0,$E8,IFERROR(INDEX(Costos!$I$23:$I$300,MATCH($B8,Costos!$A$23:$A$300,0)),0))) -> 4885.1403 | G8: Stock inicial
A9: 46244 | B9: Argollitas Classic N°4 | C9: Único | D9: 1 | F9: =IF($B9="","",N($D9)*IF(N($E9)>0,$E9,IFERROR(INDEX(Costos!$I$23:$I$300,MATCH($B9,Costos!$A$23:$A$300,0)),0))) -> 5389.1403 | G9: Stock inicial
A10: 46244 | B10: Argollitas Classic N°5 | C10: Único | D10: 2 | F10: =IF($B10="","",N($D10)*IF(N($E10)>0,$E10,IFERROR(INDEX(Costos!$I$23:$I$300,MATCH($B10,Costos!$A$23:$A$300,0)),0))) -> 11282.281 | G10: Stock inicial
A11: 46244 | B11: Cubic Mini Circulo | C11: Único | D11: 1 | F11: =IF($B11="","",N($D11)*IF(N($E11)>0,$E11,IFERROR(INDEX(Costos!$I$23:$I$300,MATCH($B11,Costos!$A$23:$A$300,0)),0))) -> 7076.6403 | G11: Stock inicial
A12: 46244 | B12: Cubic Circulo Docha | C12: Único | D12: 1 | F12: =IF($B12="","",N($D12)*IF(N($E12)>0,$E12,IFERROR(INDEX(Costos!$I$23:$I$300,MATCH($B12,Costos!$A$23:$A$300,0)),0))) -> 7436.6403 | G12: Stock inicial
A13: 46244 | B13: Cubic Cuadrado | C13: Único | D13: 1 | F13: =IF($B13="","",N($D13)*IF(N($E13)>0,$E13,IFERROR(INDEX(Costos!$I$23:$I$300,MATCH($B13,Costos!$A$23:$A$300,0)),0))) -> 6959.6403 | G13: Stock inicial
A14: 46244 | B14: Argollitas Marco Docha | C14: Único | D14: 1 | F14: =IF($B14="","",N($D14)*IF(N($E14)>0,$E14,IFERROR(INDEX(Costos!$I$23:$I$300,MATCH($B14,Costos!$A$23:$A$300,0)),0))) -> 18097.14 | G14: Stock inicial
A15: 46244 | B15: Anillo Sin Fin | C15: Mediano | D15: 1 | F15: =IF($B15="","",N($D15)*IF(N($E15)>0,$E15,IFERROR(INDEX(Costos!$I$23:$I$300,MATCH($B15,Costos!$A$23:$A$300,0)),0))) -> 12916.64 | G15: Stock inicial
A16: 46244 | B16: Anillo Circulo | C16: Chico | D16: 1 | F16: =IF($B16="","",N($D16)*IF(N($E16)>0,$E16,IFERROR(INDEX(Costos!$I$23:$I$300,MATCH($B16,Costos!$A$23:$A$300,0)),0))) -> 8741.6403 | G16: Stock inicial
A17: 46244 | B17: Anillo Circulo | C17: Mediano | D17: 1 | F17: =IF($B17="","",N($D17)*IF(N($E17)>0,$E17,IFERROR(INDEX(Costos!$I$23:$I$300,MATCH($B17,Costos!$A$23:$A$300,0)),0))) -> 8741.6403 | G17: Stock inicial
... A31: 46248 | B31: Anillo Corazón I | C31: Único | D31: 1 | F31: =IF($B31="","",N($D31)*IF(N($E31)>0,$E31,IFERROR(INDEX(Costos!$I$23:$I$300,MATCH($B31,Costos!$A$23:$A$300,0)),0))) -> 7816.6403 | G31: stock inicial
A32: 46248 | B32: Anillo Ovalo | C32: Único | D32: 1 | F32: =IF($B32="","",N($D32)*IF(N($E32)>0,$E32,IFERROR(INDEX(Costos!$I$23:$I$300,MATCH($B32,Costos!$A$23:$A$300,0)),0))) -> 5816.6403
A33: 46248 | B33: Anillo Star | C33: Único | D33: 1 | F33: =IF($B33="","",N($D33)*IF(N($E33)>0,$E33,IFERROR(INDEX(Costos!$I$23:$I$300,MATCH($B33,Costos!$A$23:$A$300,0)),0))) -> 5816.6403
A34: 46248 | B34: Anillo Nodo | C34: Único | D34: 2 | F34: =IF($B34="","",N($D34)*IF(N($E34)>0,$E34,IFERROR(INDEX(Costos!$I$23:$I$300,MATCH($B34,Costos!$A$23:$A$300,0)),0))) -> 15633.281
A35: 46248 | B35: Anillo Corazón II Plateado | C35: Único | D35: 2 | F35: =IF($B35="","",N($D35)*IF(N($E35)>0,$E35,IFERROR(INDEX(Costos!$I$23:$I$300,MATCH($B35,Costos!$A$23:$A$300,0)),0))) -> 13633.281
A36: 46248 | B36: Anillo Irregular | C36: Único | D36: 2 | F36: =IF($B36="","",N($D36)*IF(N($E36)>0,$E36,IFERROR(INDEX(Costos!$I$23:$I$300,MATCH($B36,Costos!$A$23:$A$300,0)),0))) -> 11633.281
A37: 46248 | B37: Anillo Zafira | C37: Único | D37: 2 | F37: =IF($B37="","",N($D37)*IF(N($E37)>0,$E37,IFERROR(INDEX(Costos!$I$23:$I$300,MATCH($B37,Costos!$A$23:$A$300,0)),0))) -> 15633.281
A38: 46248 | B38: Anillo Norix | C38: Único | D38: 2 | F38: =IF($B38="","",N($D38)*IF(N($E38)>0,$E38,IFERROR(INDEX(Costos!$I$23:$I$300,MATCH($B38,Costos!$A$23:$A$300,0)),0))) -> 11633.281
A39: 46249 | B39: Anillo Vanton | C39: Único | D39: 2 | F39: =IF($B39="","",N($D39)*IF(N($E39)>0,$E39,IFERROR(INDEX(Costos!$I$23:$I$300,MATCH($B39,Costos!$A$23:$A$300,0)),0))) -> 11633.281
A40: 46250 | B40: Anillo Azmira | C40: Único | D40: 1 | F40: =IF($B40="","",N($D40)*IF(N($E40)>0,$E40,IFERROR(INDEX(Costos!$I$23:$I$300,MATCH($B40,Costos!$A$23:$A$300,0)),0))) -> 5816.6403
A41: 46251 | B41: Anillo Mina | C41: Único | D41: 2 | F41: =IF($B41="","",N($D41)*IF(N($E41)>0,$E41,IFERROR(INDEX(Costos!$I$23:$I$300,MATCH($B41,Costos!$A$23:$A$300,0)),0))) -> 15633.281
A42: 46251 | B42: Anillo Virel | C42: Único | D42: 2 | F42: =IF($B42="","",N($D42)*IF(N($E42)>0,$E42,IFERROR(INDEX(Costos!$I$23:$I$300,MATCH($B42,Costos!$A$23:$A$300,0)),0))) -> 13633.281
A43: 46244 | B43: Argollitas Bubble | C43: Único | D43: 1 | F43: =IF($B43="","",N($D43)*IF(N($E43)>0,$E43,IFERROR(INDEX(Costos!$I$23:$I$300,MATCH($B43,Costos!$A$23:$A$300,0)),0))) -> 4106.6403
F44: =IF($B44="","",N($D44)*IF(N($E44)>0,$E44,IFERROR(INDEX(Costos!$I$23:$I$300,MATCH($B44,Costos!$A$23:$A$300,0)),0)))
A45: 46258 | B45: Cubic Mini cuadrado | C45: Único | D45: 2 | F45: =IF($B45="","",N($D45)*IF(N($E45)>0,$E45,IFERROR(INDEX(Costos!$I$23:$I$300,MATCH($B45,Costos!$A$23:$A$300,0)),0))) -> 9733.2807
A46: 46258 | B46: Aros Halo N°2 (14 mm) | C46: Único | D46: 2 | F46: =IF($B46="","",N($D46)*IF(N($E46)>0,$E46,IFERROR(INDEX(Costos!$I$23:$I$300,MATCH($B46,Costos!$A$23:$A$300,0)),0))) -> 29633.281
A47: 46258 | B47: Aros Gala (12 mm) | C47: Único | D47: 1 | F47: =IF($B47="","",N($D47)*IF(N($E47)>0,$E47,IFERROR(INDEX(Costos!$I$23:$I$300,MATCH($B47,Costos!$A$23:$A$300,0)),0))) -> 16866.64
A48: 46258 | B48: Argollitas 10mm | C48: Único | D48: 2 | F48: =IF($B48="","",N($D48)*IF(N($E48)>0,$E48,IFERROR(INDEX(Costos!$I$23:$I$300,MATCH($B48,Costos!$A$23:$A$300,0)),0))) -> 6533.2807
A49: 46258 | B49: Anillos Corazones III | C49: Único | D49: 1 | F49: =IF($B49="","",N($D49)*IF(N($E49)>0,$E49,IFERROR(INDEX(Costos!$I$23:$I$300,MATCH($B49,Costos!$A$23:$A$300,0)),0))) -> 15066.64
A50: 46258 | B50: Anillo Vena | C50: Único | D50: 1 | F50: =IF($B50="","",N($D50)*IF(N($E50)>0,$E50,IFERROR(INDEX(Costos!$I$23:$I$300,MATCH($B50,Costos!$A$23:$A$300,0)),0))) -> 16716.64
A51: 46258 | B51: Anillo Deriva | C51: Único | D51: 1 | F51: =IF($B51="","",N($D51)*IF(N($E51)>0,$E51,IFERROR(INDEX(Costos!$I$23:$I$300,MATCH($B51,Costos!$A$23:$A$300,0)),0))) -> 18266.64
A52: 46258 | B52: Collar Muna Circulo | C52: Único | D52: 1 | F52: =IF($B52="","",N($D52)*IF(N($E52)>0,$E52,IFERROR(INDEX(Costos!$I$23:$I$300,MATCH($B52,Costos!$A$23:$A$300,0)),0))) -> 18566.64
A53: 46258 | B53: Collar Muna Corazón | C53: Único | D53: 1 | F53: =IF($B53="","",N($D53)*IF(N($E53)>0,$E53,IFERROR(INDEX(Costos!$I$23:$I$300,MATCH($B53,Costos!$A$23:$A$300,0)),0))) -> 19466.64
A54: 46258 | B54: Collar Fino Circulo | C54: Único | D54: 1 | F54: =IF($B54="","",N($D54)*IF(N($E54)>0,$E54,IFERROR(INDEX(Costos!$I$23:$I$300,MATCH($B54,Costos!$A$23:$A$300,0)),0))) -> 18916.64
...

Sheet Ventas
A1: VENTAS
A2: Una línea por cada venta. Elegí el producto de la lista y poné el talle solo si es anillo.
A3: Dejá el precio vacío para que tome tu precio de venta. Escribilo solo si hiciste un precio especial.
A5: Fecha | B5: Producto | C5: Talle | D5: Cantidad | E5: Precio unitario | F5: Total | G5: Clienta | H5: Notas
A6: 46243 | B6: Anillo calado | C6: Mediano | D6: 1 | F6: =IF($B6="","",N($D6)*IF(N($E6)>0,$E6,IFERROR(INDEX(Costos!$K$23:$K$300,MATCH($B6,Costos!$A$23:$A$300,0)),0))) -> 19000 | G6: gabi de simone
A7: 46243 | B7: Anillo calado | C7: Grande | D7: 1 | F7: =IF($B7="","",N($D7)*IF(N($E7)>0,$E7,IFERROR(INDEX(Costos!$K$23:$K$300,MATCH($B7,Costos!$A$23:$A$300,0)),0))) -> 19000 | G7: gabi de simone
A8: 46243 | B8: Cadena lisa | C8: Único | D8: 1 | F8: =IF($B8="","",N($D8)*IF(N($E8)>0,$E8,IFERROR(INDEX(Costos!$K$23:$K$300,MATCH($B8,Costos!$A$23:$A$300,0)),0))) -> 7000 | G8: gabi de simone
A9: 46251 | B9: Cubic Circulo Docha | C9: Único | D9: 1 | F9: =IF($B9="","",N($D9)*IF(N($E9)>0,$E9,IFERROR(INDEX(Costos!$K$23:$K$300,MATCH($B9,Costos!$A$23:$A$300,0)),0))) -> 12500 | G9: abueka
A10: 46251 | B10: Argollitas Classic N°1 | C10: Único | D10: 1 | F10: =IF($B10="","",N($D10)*IF(N($E10)>0,$E10,IFERROR(INDEX(Costos!$K$23:$K$300,MATCH($B10,Costos!$A$23:$A$300,0)),0))) -> 7000 | G10: valen
A11: 46251 | B11: Argollitas Classic N°2 | C11: Único | D11: 1 | F11: =IF($B11="","",N($D11)*IF(N($E11)>0,$E11,IFERROR(INDEX(Costos!$K$23:$K$300,MATCH($B11,Costos!$A$23:$A$300,0)),0))) -> 7500 | G11: valen
A12: 46251 | B12: Argollitas gota | C12: Único | D12: 1 | F12: =IF($B12="","",N($D12)*IF(N($E12)>0,$E12,IFERROR(INDEX(Costos!$K$23:$K$300,MATCH($B12,Costos!$A$23:$A$300,0)),0))) -> 7500 | G12: valen
A13: 46252 | B13: Anillo Ovalo | C13: Único | D13: 1 | F13: =IF($B13="","",N($D13)*IF(N($E13)>0,$E13,IFERROR(INDEX(Costos!$K$23:$K$300,MATCH($B13,Costos!$A$23:$A$300,0)),0))) -> 11500 | G13: valen
A14: 46252 | B14: Anillo Irregular | C14: Único | D14: 1 | F14: =IF($B14="","",N($D14)*IF(N($E14)>0,$E14,IFERROR(INDEX(Costos!$K$23:$K$300,MATCH($B14,Costos!$A$23:$A$300,0)),0))) -> 11500 | G14: valen
A15: 46254 | B15: Anillo Vanton | C15: Único | D15: 1 | F15: =IF($B15="","",N($D15)*IF(N($E15)>0,$E15,IFERROR(INDEX(Costos!$K$23:$K$300,MATCH($B15,Costos!$A$23:$A$300,0)),0))) -> 11500 | G15: caro
A16: 46254 | B16: Anillo Zafira | C16: Único | D16: 1 | F16: =IF($B16="","",N($D16)*IF(N($E16)>0,$E16,IFERROR(INDEX(Costos!$K$23:$K$300,MATCH($B16,Costos!$A$23:$A$300,0)),0))) -> 13000 | G16: caro
A17: 46254 | B17: Anillo Sin Fin | C17: Mediano | D17: 1 | F17: =IF($B17="","",N($D17)*IF(N($E17)>0,$E17,IFERROR(INDEX(Costos!$K$23:$K$300,MATCH($B17,Costos!$A$23:$A$300,0)),0))) -> 20000 | G17: vicky
A18: 46254 | B18: Anillo Vanton | C18: Único | D18: 1 | E18: 0 | F18: =IF($B18="","",N($D18)*IF(N($E18)>0,$E18,IFERROR(INDEX(Costos!$K$23:$K$300,MATCH($B18,Costos!$A$23:$A$300,0)),0))) -> 11500 | G18: LO PERDI
A19: 46254 | B19: Anillo Nodo | C19: Único | D19: 1 | F19: =IF($B19="","",N($D19)*IF(N($E19)>0,$E19,IFERROR(INDEX(Costos!$K$23:$K$300,MATCH($B19,Costos!$A$23:$A$300,0)),0))) -> 13000 | G19: abuela para regalo gabi
A20: 46254 | B20: Anillo Virel | C20: Único | D20: 1 | F20: =IF($B20="","",N($D20)*IF(N($E20)>0,$E20,IFERROR(INDEX(Costos!$K$23:$K$300,MATCH($B20,Costos!$A$23:$A$300,0)),0))) -> 12000 | G20: abuela para regalo gabi
A21: 46256 | B21: Cubic Mini Circulo | C21: Único | D21: 1 | F21: =IF($B21="","",N($D21)*IF(N($E21)>0,$E21,IFERROR(INDEX(Costos!$K$23:$K$300,MATCH($B21,Costos!$A$23:$A$300,0)),0))) -> 12000 | G21: mica
A22: 46256 | B22: Anillo Azmira | C22: Único | D22: 1 | F22: =IF($B22="","",N($D22)*IF(N($E22)>0,$E22,IFERROR(INDEX(Costos!$K$23:$K$300,MATCH($B22,Costos!$A$23:$A$300,0)),0))) -> 11500 | G22: abuela piqui
A23: 46256 | B23: Anillo Gota | C23: Mediano | D23: 1 | F23: =IF($B23="","",N($D23)*IF(N($E23)>0,$E23,IFERROR(INDEX(Costos!$K$23:$K$300,MATCH($B23,Costos!$A$23:$A$300,0)),0))) -> 23000 | G23: abuela piqui
A24: 46256 | B24: Anillo Mina | C24: Único | D24: 1 | F24: =IF($B24="","",N($D24)*IF(N($E24)>0,$E24,IFERROR(INDEX(Costos!$K$23:$K$300,MATCH($B24,Costos!$A$23:$A$300,0)),0))) -> 13000 | G24: tia nariana
A25: 46256 | B25: Anillo Virel | C25: Único | D25: 1 | F25: =IF($B25="","",N($D25)*IF(N($E25)>0,$E25,IFERROR(INDEX(Costos!$K$23:$K$300,MATCH($B25,Costos!$A$23:$A$300,0)),0))) -> 12000 | G25: tia nariana
A26: 46256 | B26: Anillo Mina | C26: Único | D26: 1 | E26: 0 | F26: =IF($B26="","",N($D26)*IF(N($E26)>0,$E26,IFERROR(INDEX(Costos!$K$23:$K$300,MATCH($B26,Costos!$A$23:$A$300,0)),0))) -> 13000 | G26: VALEN | H26: SE ROMPIO
A27: 46258 | B27: Anillo Circulo | C27: Chico | D27: 1 | F27: =IF($B27="","",N($D27)*IF(N($E27)>0,$E27,IFERROR(INDEX(Costos!$K$23:$K$300,MATCH($B27,Costos!$A$23:$A$300,0)),0))) -> 16000 | G27: gabi de simone | H27: PARA LA HERMANA
A28: 46258 | B28: Argollitas Classic N°3 | C28: Único | D28: 1 | F28: =IF($B28="","",N($D28)*IF(N($E28)>0,$E28,IFERROR(INDEX(Costos!$K$23:$K$300,MATCH($B28,Costos!$A$23:$A$300,0)),0))) -> 8000 | G28: gabi de simone | H28: PARA LA HERMANA
A29: 46258 | B29: Argollitas Classic N°4 | C29: Único | D29: 1 | E29: 0 | F29: =IF($B29="","",N($D29)*IF(N($E29)>0,$E29,IFERROR(INDEX(Costos!$K$23:$K$300,MATCH($B29,Costos!$A$23:$A$300,0)),0))) -> 8500 | G29: está fallado | H29: SE ROMPIO
A30: 46260 | B30: Argollitas 10mm | C30: Único | D30: 1 | E30: 0 | F30: =IF($B30="","",N($D30)*IF(N($E30)>0,$E30,IFERROR(INDEX(Costos!$K$23:$K$300,MATCH($B30,Costos!$A$23:$A$300,0)),0))) -> 7000 | G30: se me rompio | H30: SE ROMPIO
A31: 46260 | B31: Cubic Mini cuadrado | C31: Único | D31: 1 | F31: =IF($B31="","",N($D31)*IF(N($E31)>0,$E31,IFERROR(INDEX(Costos!$K$23:$K$300,MATCH($B31,Costos!$A$23:$A$300,0)),0))) -> 12000 | G31: lola gogo
A32: 46260 | B32: Anillo Vena | C32: Único | D32: 1 | F32: =IF($B32="","",N($D32)*IF(N($E32)>0,$E32,IFERROR(INDEX(Costos!$K$23:$K$300,MATCH($B32,Costos!$A$23:$A$300,0)),0))) -> 25000 | G32: lola gogo
A33: 46260 | B33: Collar Muna Circulo | C33: Único | D33: 1 | F33: =IF($B33="","",N($D33)*IF(N($E33)>0,$E33,IFERROR(INDEX(Costos!$K$23:$K$300,MATCH($B33,Costos!$A$23:$A$300,0)),0))) -> 30000 | G33: gabriela juliano (mama
A34: 46260 | B34: Collar Fino Circulo | C34: Único | D34: 1 | F34: =IF($B34="","",N($D34)*IF(N($E34)>0,$E34,IFERROR(INDEX(Costos!$K$23:$K$300,MATCH($B34,Costos!$A$23:$A$300,0)),0))) -> 28000 | G34: abuela
A35: 46261 | B35: Anillos Corazones III | C35: Único | D35: 1 | F35: =IF($B35="","",N($D35)*IF(N($E35)>0,$E35,IFERROR(INDEX(Costos!$K$23:$K$300,MATCH($B35,Costos!$A$23:$A$300,0)),0))) -> 23500 | G35: vicky
A36: 46261 | B36: Collar Muna Corazón | C36: Único | D36: 1 | F36: =IF($B36="","",N($D36)*IF(N($E36)>0,$E36,IFERROR(INDEX(Costos!$K$23:$K$300,MATCH($B36,Costos!$A$23:$A$300,0)),0))) -> 31000 | G36: nico leandro grinfield
A37: 46261 | B37: Argollitas Caviar circulo | C37: Único | D37: 1 | F37: =IF($B37="","",N($D37)*IF(N($E37)>0,$E37,IFERROR(INDEX(Costos!$K$23:$K$300,MATCH($B37,Costos!$A$23:$A$300,0)),0))) -> 6500 | G37: nico leandro grinfield
A38: 46261 | B38: Anillo Sin Fin | C38: Mediano | D38: 1 | F38: =IF($B38="","",N($D38)*IF(N($E38)>0,$E38,IFERROR(INDEX(Costos!$K$23:$K$300,MATCH($B38,Costos!$A$23:$A$300,0)),0))) -> 20000 | G38: gaby de simone
A39: 46261 | B39: Anillo Irregular | C39: Único | D39: 1 | F39: =IF($B39="","",N($D39)*IF(N($E39)>0,$E39,IFERROR(INDEX(Costos!$K$23:$K$300,MATCH($B39,Costos!$A$23:$A$300,0)),0))) -> 11500 | G39: gaby de simone
A40: 46261 | B40: Cubic Mini cuadrado | C40: Único | D40: 1 | F40: =IF($B40="","",N($D40)*IF(N($E40)>0,$E40,IFERROR(INDEX(Costos!$K$23:$K$300,MATCH($B40,Costos!$A$23:$A$300,0)),0))) -> 12000 | G40: juli mama
A41: 46261 | B41: Anillo Sin Fin | C41: Mediano | D41: 1 | F41: =IF($B41="","",N($D41)*IF(N($E41)>0,$E41,IFERROR(INDEX(Costos!$K$23:$K$300,MATCH($B41,Costos!$A$23:$A$300,0)),0))) -> 20000 | G41: juli mama
...

Sheet Stock
A1: STOCK
A2: Esta hoja se calcula sola desde Compras y Ventas. Acá no cargues nada.
A3: Para descontar una venta, agregá la línea en la hoja Ventas.
A5: Avisame cuando queden | B5: 1 | C5: o menos | E5: Piezas en stock | F5: =SUM(H9:H108) -> 69 | H5: Invertido: | I5: =SUM(Compras!F:F) -> 1321362.3 | J5: Facturado: | K5: =SUM(Ventas!$F$6:$F$605) -> 978500 | L5: Ganancia: | M5: {=SUM(Ventas!F:F)-SUMPRODUCT(Ventas!D6:D1000,IFERROR(VLOOKUP(Ventas!B6:B1000,Costos!A:I,9,FALSE()),0))} -> 412618.9 | N5: pasa eso porque todavia no vendi todo lo que esta en stock
A8: Producto | B8: Material | C8: Categoría | D8: Único | E8: Chico | F8: Mediano | G8: Grande | H8: Total | I8: Estado | J8: Vendidas | K8: Facturado
A9: =IF(Costos!$A23="","",Costos!$A23) -> Argollitas Classic N°1 | B9: =IF(Costos!$A23="","",Costos!$B23&"") -> Plata 925 | C9: =IF(Costos!$A23="","",Costos!$C23&"") -> Aros | D9: =IF($A9="","",SUMIFS(Compras!$D$6:$D$605,Compras!$B$6:$B$605,$A9,Compras!$C$6:$C$605,"Único")-SUMIFS(Ventas!$D$6:$D$605,Ventas!$B$6:$B$605,$A9,Ventas!$C$6:$C$605,"Único")) -> 0 | E9: =IF($A9="","",IF(LEFT($C9,6)="Anillo",SUMIFS(Compras!$D$6:$D$605,Compras!$B$6:$B$605,$A9,Compras!$C$6:$C$605,"Chico")-SUMIFS(Ventas!$D$6:$D$605,Ventas!$B$6:$B$605,$A9,Ventas!$C$6:$C$605,"Chico"),"")) | F9: =IF($A9="","",IF(LEFT($C9,6)="Anillo",SUMIFS(Compras!$D$6:$D$605,Compras!$B$6:$B$605,$A9,Compras!$C$6:$C$605,"Mediano")-SUMIFS(Ventas!$D$6:$D$605,Ventas!$B$6:$B$605,$A9,Ventas!$C$6:$C$605,"Mediano"),"")) | G9: =IF($A9="","",IF(LEFT($C9,6)="Anillo",SUMIFS(Compras!$D$6:$D$605,Compras!$B$6:$B$605,$A9,Compras!$C$6:$C$605,"Grande")-SUMIFS(Ventas!$D$6:$D$605,Ventas!$B$6:$B$605,$A9,Ventas!$C$6:$C$605,"Grande"),"")) | H9: =IF($A9="","",N($D9)+N($E9)+N($F9)+N($G9)) -> 0 | I9: =IF($A9="","",IF(N($H9)<=0,"SIN STOCK",IF(LEFT($C9,6)="Anillo",IF(IF(AND(SUMIFS(Compras!$D$6:$D$605,Compras!$B$6:$B$605,$A9,Compras!$C$6:$C$605,"Chico")>0,N($E9)<=$B$5),"C ","")&IF(AND(SUMIFS(Compras!$D$6:$D$605,Compras!$B$6:$B$605,$A9,Compras!$C$6:$C$605,"Mediano")>0,N($F9)<=$B$5),"M ","")&IF(AND(SUMIFS(Compras!$D$6:$D$605,Compras!$B$6:$B$605,$A9,Compras!$C$6:$C$605,"Grande")>0,N($G9)<=$B$5),"G","")="","","Reponer "&IF(AND(SUMIFS(Compras!$D$6:$D$605,Compras!$B$6:$B$605,$A9,Compras!$C$6:$C$605,"Chico")>0,N($E9)<=$B$5),"C ","")&IF(AND(SUMIFS(Compras!$D$6:$D$605,Compras!$B$6:$B$605,$A9,Compras!$C$6:$C$605,"Mediano")>0,N($F9)<=$B$5),"M ","")&IF(AND(SUMIFS(Compras!$D$6:$D$605,Compras!$B$6:$B$605,$A9,Compras!$C$6:$C$605,"Grande")>0,N($G9)<=$B$5),"G","")),IF(N($H9)<=$B$5,"REPONER","")))) -> SIN STOCK | J9: =IF($A9="","",SUMIFS(Ventas!$D$6:$D$605,Ventas!$B$6:$B$605,$A9)) -> 1 | K9: =IF($A9="","",SUMIFS(Ventas!$F$6:$F$605,Ventas!$B$6:$B$605,$A9)) -> 7000
A10: =IF(Costos!$A24="","",Costos!$A24) -> Argollitas Classic N°2 | B10: =IF(Costos!$A24="","",Costos!$B24&"") -> Plata 925 | C10: =IF(Costos!$A24="","",Costos!$C24&"") -> Aros | D10: =IF($A10="","",SUMIFS(Compras!$D$6:$D$605,Compras!$B$6:$B$605,$A10,Compras!$C$6:$C$605,"Único")-SUMIFS(Ventas!$D$6:$D$605,Ventas!$B$6:$B$605,$A10,Ventas!$C$6:$C$605,"Único")) -> 0 | E10: =IF($A10="","",IF(LEFT($C10,6)="Anillo",SUMIFS(Compras!$D$6:$D$605,Compras!$B$6:$B$605,$A10,Compras!$C$6:$C$605,"Chico")-SUMIFS(Ventas!$D$6:$D$605,Ventas!$B$6:$B$605,$A10,Ventas!$C$6:$C$605,"Chico"),"")) | F10: =IF($A10="","",IF(LEFT($C10,6)="Anillo",SUMIFS(Compras!$D$6:$D$605,Compras!$B$6:$B$605,$A10,Compras!$C$6:$C$605,"Mediano")-SUMIFS(Ventas!$D$6:$D$605,Ventas!$B$6:$B$605,$A10,Ventas!$C$6:$C$605,"Mediano"),"")) | G10: =IF($A10="","",IF(LEFT($C10,6)="Anillo",SUMIFS(Compras!$D$6:$D$605,Compras!$B$6:$B$605,$A10,Compras!$C$6:$C$605,"Grande")-SUMIFS(Ventas!$D$6:$D$605,Ventas!$B$6:$B$605,$A10,Ventas!$C$6:$C$605,"Grande"),"")) | H10: =IF($A10="","",N($D10)+N($E10)+N($F10)+N($G10)) -> 0 | I10: =IF($A10="","",IF(N($H10)<=0,"SIN STOCK",IF(LEFT($C10,6)="Anillo",IF(IF(AND(SUMIFS(Compras!$D$6:$D$605,Compras!$B$6:$B$605,$A10,Compras!$C$6:$C$605,"Chico")>0,N($E10)<=$B$5),"C ","")&IF(AND(SUMIFS(Compras!$D$6:$D$605,Compras!$B$6:$B$605,$A10,Compras!$C$6:$C$605,"Mediano")>0,N($F10)<=$B$5),"M ","")&IF(AND(SUMIFS(Compras!$D$6:$D$605,Compras!$B$6:$B$605,$A10,Compras!$C$6:$C$605,"Grande")>0,N($G10)<=$B$5),"G","")="","","Reponer "&IF(AND(SUMIFS(Compras!$D$6:$D$605,Compras!$B$6:$B$605,$A10,Compras!$C$6:$C$605,"Chico")>0,N($E10)<=$B$5),"C ","")&IF(AND(SUMIFS(Compras!$D$6:$D$605,Compras!$B$6:$B$605,$A10,Compras!$C$6:$C$605,"Mediano")>0,N($F10)<=$B$5),"M ","")&IF(AND(SUMIFS(Compras!$D$6:$D$605,Compras!$B$6:$B$605,$A10,Compras!$C$6:$C$605,"Grande")>0,N($G10)<=$B$5),"G","")),IF(N($H10)<=$B$5,"REPONER","")))) -> SIN STOCK | J10: =IF($A10="","",SUMIFS(Ventas!$D$6:$D$605,Ventas!$B$6:$B$605,$A10)) -> 1 | K10: =IF($A10="","",SUMIFS(Ventas!$F$6:$F$605,Ventas!$B$6:$B$605,$A10)) -> 7500
A11: =IF(Costos!$A25="","",Costos!$A25) -> Argollitas Classic N°3 | B11: =IF(Costos!$A25="","",Costos!$B25&"") -> Plata 925 | C11: =IF(Costos!$A25="","",Costos!$C25&"") -> Aros | D11: =IF($A11="","",SUMIFS(Compras!$D$6:$D$605,Compras!$B$6:$B$605,$A11,Compras!$C$6:$C$605,"Único")-SUMIFS(Ventas!$D$6:$D$605,Ventas!$B$6:$B$605,$A11,Ventas!$C$6:$C$605,"Único")) -> 0 | E11: =IF($A11="","",IF(LEFT($C11,6)="Anillo",SUMIFS(Compras!$D$6:$D$605,Compras!$B$6:$B$605,$A11,Compras!$C$6:$C$605,"Chico")-SUMIFS(Ventas!$D$6:$D$605,Ventas!$B$6:$B$605,$A11,Ventas!$C$6:$C$605,"Chico"),"")) | F11: =IF($A11="","",IF(LEFT($C11,6)="Anillo",SUMIFS(Compras!$D$6:$D$605,Compras!$B$6:$B$605,$A11,Compras!$C$6:$C$605,"Mediano")-SUMIFS(Ventas!$D$6:$D$605,Ventas!$B$6:$B$605,$A11,Ventas!$C$6:$C$605,"Mediano"),"")) | G11: =IF($A11="","",IF(LEFT($C11,6)="Anillo",SUMIFS(Compras!$D$6:$D$605,Compras!$B$6:$B$605,$A11,Compras!$C$6:$C$605,"Grande")-SUMIFS(Ventas!$D$6:$D$605,Ventas!$B$6:$B$605,$A11,Ventas!$C$6:$C$605,"Grande"),"")) | H11: =IF($A11="","",N($D11)+N($E11)+N($F11)+N($G11)) -> 0 | I11: =IF($A11="","",IF(N($H11)<=0,"SIN STOCK",IF(LEFT($C11,6)="Anillo",IF(IF(AND(SUMIFS(Compras!$D$6:$D$605,Compras!$B$6:$B$605,$A11,Compras!$C$6:$C$605,"Chico")>0,N($E11)<=$B$5),"C ","")&IF(AND(SUMIFS(Compras!$D$6:$D$605,Compras!$B$6:$B$605,$A11,Compras!$C$6:$C$605,"Mediano")>0,N($F11)<=$B$5),"M ","")&IF(AND(SUMIFS(Compras!$D$6:$D$605,Compras!$B$6:$B$605,$A11,Compras!$C$6:$C$605,"Grande")>0,N($G11)<=$B$5),"G","")="","","Reponer "&IF(AND(SUMIFS(Compras!$D$6:$D$605,Compras!$B$6:$B$605,$A11,Compras!$C$6:$C$605,"Chico")>0,N($E11)<=$B$5),"C ","")&IF(AND(SUMIFS(Compras!$D$6:$D$605,Compras!$B$6:$B$605,$A11,Compras!$C$6:$C$605,"Mediano")>0,N($F11)<=$B$5),"M ","")&IF(AND(SUMIFS(Compras!$D$6:$D$605,Compras!$B$6:$B$605,$A11,Compras!$C$6:$C$605,"Grande")>0,N($G11)<=$B$5),"G","")),IF(N($H11)<=$B$5,"REPONER","")))) -> SIN STOCK | J11: =IF($A11="","",SUMIFS(Ventas!$D$6:$D$605,Ventas!$B$6:$B$605,$A11)) -> 1 | K11: =IF($A11="","",SUMIFS(Ventas!$F$6:$F$605,Ventas!$B$6:$B$605,$A11)) -> 8000
A12: =IF(Costos!$A26="","",Costos!$A26) -> Argollitas Classic N°4 | B12: =IF(Costos!$A26="","",Costos!$B26&"") -> Plata 925 | C12: =IF(Costos!$A26="","",Costos!$C26&"") -> Aros | D12: =IF($A12="","",SUMIFS(Compras!$D$6:$D$605,Compras!$B$6:$B$605,$A12,Compras!$C$6:$C$605,"Único")-SUMIFS(Ventas!$D$6:$D$605,Ventas!$B$6:$B$605,$A12,Ventas!$C$6:$C$605,"Único")) -> 0 | E12: =IF($A12="","",IF(LEFT($C12,6)="Anillo",SUMIFS(Compras!$D$6:$D$605,Compras!$B$6:$B$605,$A12,Compras!$C$6:$C$605,"Chico")-SUMIFS(Ventas!$D$6:$D$605,Ventas!$B$6:$B$605,$A12,Ventas!$C$6:$C$605,"Chico"),"")) | F12: =IF($A12="","",IF(LEFT($C12,6)="Anillo",SUMIFS(Compras!$D$6:$D$605,Compras!$B$6:$B$605,$A12,Compras!$C$6:$C$605,"Mediano")-SUMIFS(Ventas!$D$6:$D$605,Ventas!$B$6:$B$605,$A12,Ventas!$C$6:$C$605,"Mediano"),"")) | G12: =IF($A12="","",IF(LEFT($C12,6)="Anillo",SUMIFS(Compras!$D$6:$D$605,Compras!$B$6:$B$605,$A12,Compras!$C$6:$C$605,"Grande")-SUMIFS(Ventas!$D$6:$D$605,Ventas!$B$6:$B$605,$A12,Ventas!$C$6:$C$605,"Grande"),"")) | H12: =IF($A12="","",N($D12)+N($E12)+N($F12)+N($G12)) -> 0 | I12: =IF($A12="","",IF(N($H12)<=0,"SIN STOCK",IF(LEFT($C12,6)="Anillo",IF(IF(AND(SUMIFS(Compras!$D$6:$D$605,Compras!$B$6:$B$605,$A12,Compras!$C$6:$C$605,"Chico")>0,N($E12)<=$B$5),"C ","")&IF(AND(SUMIFS(Compras!$D$6:$D$605,Compras!$B$6:$B$605,$A12,Compras!$C$6:$C$605,"Mediano")>0,N($F12)<=$B$5),"M ","")&IF(AND(SUMIFS(Compras!$D$6:$D$605,Compras!$B$6:$B$605,$A12,Compras!$C$6:$C$605,"Grande")>0,N($G12)<=$B$5),"G","")="","","Reponer "&IF(AND(SUMIFS(Compras!$D$6:$D$605,Compras!$B$6:$B$605,$A12,Compras!$C$6:$C$605,"Chico")>0,N($E12)<=$B$5),"C ","")&IF(AND(SUMIFS(Compras!$D$6:$D$605,Compras!$B$6:$B$605,$A12,Compras!$C$6:$C$605,"Mediano")>0,N($F12)<=$B$5),"M ","")&IF(AND(SUMIFS(Compras!$D$6:$D$605,Compras!$B$6:$B$605,$A12,Compras!$C$6:$C$605,"Grande")>0,N($G12)<=$B$5),"G","")),IF(N($H12)<=$B$5,"REPONER","")))) -> SIN STOCK | J12: =IF($A12="","",SUMIFS(Ventas!$D$6:$D$605,Ventas!$B$6:$B$605,$A12)) -> 1 | K12: =IF($A12="","",SUMIFS(Ventas!$F$6:$F$605,Ventas!$B$6:$B$605,$A12)) -> 8500
A13: =IF(Costos!$A27="","",Costos!$A27) -> Argollitas Classic N°5 | B13: =IF(Costos!$A27="","",Costos!$B27&"") -> Plata 925 | C13: =IF(Costos!$A27="","",Costos!$C27&"") -> Aros | D13: =IF($A13="","",SUMIFS(Compras!$D$6:$D$605,Compras!$B$6:$B$605,$A13,Compras!$C$6:$C$605,"Único")-SUMIFS(Ventas!$D$6:$D$605,Ventas!$B$6:$B$605,$A13,Ventas!$C$6:$C$605,"Único")) -> 1 | E13: =IF($A13="","",IF(LEFT($C13,6)="Anillo",SUMIFS(Compras!$D$6:$D$605,Compras!$B$6:$B$605,$A13,Compras!$C$6:$C$605,"Chico")-SUMIFS(Ventas!$D$6:$D$605,Ventas!$B$6:$B$605,$A13,Ventas!$C$6:$C$605,"Chico"),"")) | F13: =IF($A13="","",IF(LEFT($C13,6)="Anillo",SUMIFS(Compras!$D$6:$D$605,Compras!$B$6:$B$605,$A13,Compras!$C$6:$C$605,"Mediano")-SUMIFS(Ventas!$D$6:$D$605,Ventas!$B$6:$B$605,$A13,Ventas!$C$6:$C$605,"Mediano"),"")) | G13: =IF($A13="","",IF(LEFT($C13,6)="Anillo",SUMIFS(Compras!$D$6:$D$605,Compras!$B$6:$B$605,$A13,Compras!$C$6:$C$605,"Grande")-SUMIFS(Ventas!$D$6:$D$605,Ventas!$B$6:$B$605,$A13,Ventas!$C$6:$C$605,"Grande"),"")) | H13: =IF($A13="","",N($D13)+N($E13)+N($F13)+N($G13)) -> 1 | I13: =IF($A13="","",IF(N($H13)<=0,"SIN STOCK",IF(LEFT($C13,6)="Anillo",IF(IF(AND(SUMIFS(Compras!$D$6:$D$605,Compras!$B$6:$B$605,$A13,Compras!$C$6:$C$605,"Chico")>0,N($E13)<=$B$5),"C ","")&IF(AND(SUMIFS(Compras!$D$6:$D$605,Compras!$B$6:$B$605,$A13,Compras!$C$6:$C$605,"Mediano")>0,N($F13)<=$B$5),"M ","")&IF(AND(SUMIFS(Compras!$D$6:$D$605,Compras!$B$6:$B$605,$A13,Compras!$C$6:$C$605,"Grande")>0,N($G13)<=$B$5),"G","")="","","Reponer "&IF(AND(SUMIFS(Compras!$D$6:$D$605,Compras!$B$6:$B$605,$A13,Compras!$C$6:$C$605,"Chico")>0,N($E13)<=$B$5),"C ","")&IF(AND(SUMIFS(Compras!$D$6:$D$605,Compras!$B$6:$B$605,$A13,Compras!$C$6:$C$605,"Mediano")>0,N($F13)<=$B$5),"M ","")&IF(AND(SUMIFS(Compras!$D$6:$D$605,Compras!$B$6:$B$605,$A13,Compras!$C$6:$C$605,"Grande")>0,N($G13)<=$B$5),"G","")),IF(N($H13)<=$B$5,"REPONER","")))) -> REPONER | J13: =IF($A13="","",SUMIFS(Ventas!$D$6:$D$605,Ventas!$B$6:$B$605,$A13)) -> 1 | K13: =IF($A13="","",SUMIFS(Ventas!$F$6:$F$605,Ventas!$B$6:$B$605,$A13)) -> 9000
A14: =IF(Costos!$A28="","",Costos!$A28) -> Cubic Mini Circulo | B14: =IF(Costos!$A28="","",Costos!$B28&"") -> Plata 925 | C14: =IF(Costos!$A28="","",Costos!$C28&"") -> Aros | D14: =IF($A14="","",SUMIFS(Compras!$D$6:$D$605,Compras!$B$6:$B$605,$A14,Compras!$C$6:$C$605,"Único")-SUMIFS(Ventas!$D$6:$D$605,Ventas!$B$6:$B$605,$A14,Ventas!$C$6:$C$605,"Único")) -> 0 | E14: =IF($A14="","",IF(LEFT($C14,6)="Anillo",SUMIFS(Compras!$D$6:$D$605,Compras!$B$6:$B$605,$A14,Compras!$C$6:$C$605,"Chico")-SUMIFS(Ventas!$D$6:$D$605,Ventas!$B$6:$B$605,$A14,Ventas!$C$6:$C$605,"Chico"),"")) | F14: =IF($A14="","",IF(LEFT($C14,6)="Anillo",SUMIFS(Compras!$D$6:$D$605,Compras!$B$6:$B$605,$A14,Compras!$C$6:$C$605,"Mediano")-SUMIFS(Ventas!$D$6:$D$605,Ventas!$B$6:$B$605,$A14,Ventas!$C$6:$C$605,"Mediano"),"")) | G14: =IF($A14="","",IF(LEFT($C14,6)="Anillo",SUMIFS(Compras!$D$6:$D$605,Compras!$B$6:$B$605,$A14,Compras!$C$6:$C$605,"Grande")-SUMIFS(Ventas!$D$6:$D$605,Ventas!$B$6:$B$605,$A14,Ventas!$C$6:$C$605,"Grande"),"")) | H14: =IF($A14="","",N($D14)+N($E14)+N($F14)+N($G14)) -> 0 | I14: =IF($A14="","",IF(N($H14)<=0,"SIN STOCK",IF(LEFT($C14,6)="Anillo",IF(IF(AND(SUMIFS(Compras!$D$6:$D$605,Compras!$B$6:$B$605,$A14,Compras!$C$6:$C$605,"Chico")>0,N($E14)<=$B$5),"C ","")&IF(AND(SUMIFS(Compras!$D$6:$D$605,Compras!$B$6:$B$605,$A14,Compras!$C$6:$C$605,"Mediano")>0,N($F14)<=$B$5),"M ","")&IF(AND(SUMIFS(Compras!$D$6:$D$605,Compras!$B$6:$B$605,$A14,Compras!$C$6:$C$605,"Grande")>0,N($G14)<=$B$5),"G","")="","","Reponer "&IF(AND(SUMIFS(Compras!$D$6:$D$605,Compras!$B$6:$B$605,$A14,Compras!$C$6:$C$605,"Chico")>0,N($E14)<=$B$5),"C ","")&IF(AND(SUMIFS(Compras!$D$6:$D$605,Compras!$B$6:$B$605,$A14,Compras!$C$6:$C$605,"Mediano")>0,N($F14)<=$B$5),"M ","")&IF(AND(SUMIFS(Compras!$D$6:$D$605,Compras!$B$6:$B$605,$A14,Compras!$C$6:$C$605,"Grande")>0,N($G14)<=$B$5),"G","")),IF(N($H14)<=$B$5,"REPONER","")))) -> SIN STOCK | J14: =IF($A14="","",SUMIFS(Ventas!$D$6:$D$605,Ventas!$B$6:$B$605,$A14)) -> 1 | K14: =IF($A14="","",SUMIFS(Ventas!$F$6:$F$605,Ventas!$B$6:$B$605,$A14)) -> 12000
A15: =IF(Costos!$A29="","",Costos!$A29) -> Cubic Circulo Docha | B15: =IF(Costos!$A29="","",Costos!$B29&"") -> Plata 925 | C15: =IF(Costos!$A29="","",Costos!$C29&"") -> Aros | D15: =IF($A15="","",SUMIFS(Compras!$D$6:$D$605,Compras!$B$6:$B$605,$A15,Compras!$C$6:$C$605,"Único")-SUMIFS(Ventas!$D$6:$D$605,Ventas!$B$6:$B$605,$A15,Ventas!$C$6:$C$605,"Único")) -> 0 | E15: =IF($A15="","",IF(LEFT($C15,6)="Anillo",SUMIFS(Compras!$D$6:$D$605,Compras!$B$6:$B$605,$A15,Compras!$C$6:$C$605,"Chico")-SUMIFS(Ventas!$D$6:$D$605,Ventas!$B$6:$B$605,$A15,Ventas!$C$6:$C$605,"Chico"),"")) | F15: =IF($A15="","",IF(LEFT($C15,6)="Anillo",SUMIFS(Compras!$D$6:$D$605,Compras!$B$6:$B$605,$A15,Compras!$C$6:$C$605,"Mediano")-SUMIFS(Ventas!$D$6:$D$605,Ventas!$B$6:$B$605,$A15,Ventas!$C$6:$C$605,"Mediano"),"")) | G15: =IF($A15="","",IF(LEFT($C15,6)="Anillo",SUMIFS(Compras!$D$6:$D$605,Compras!$B$6:$B$605,$A15,Compras!$C$6:$C$605,"Grande")-SUMIFS(Ventas!$D$6:$D$605,Ventas!$B$6:$B$605,$A15,Ventas!$C$6:$C$605,"Grande"),"")) | H15: =IF($A15="","",N($D15)+N($E15)+N($F15)+N($G15)) -> 0 | I15: =IF($A15="","",IF(N($H15)<=0,"SIN STOCK",IF(LEFT($C15,6)="Anillo",IF(IF(AND(SUMIFS(Compras!$D$6:$D$605,Compras!$B$6:$B$605,$A15,Compras!$C$6:$C$605,"Chico")>0,N($E15)<=$B$5),"C ","")&IF(AND(SUMIFS(Compras!$D$6:$D$605,Compras!$B$6:$B$605,$A15,Compras!$C$6:$C$605,"Mediano")>0,N($F15)<=$B$5),"M ","")&IF(AND(SUMIFS(Compras!$D$6:$D$605,Compras!$B$6:$B$605,$A15,Compras!$C$6:$C$605,"Grande")>0,N($G15)<=$B$5),"G","")="","","Reponer "&IF(AND(SUMIFS(Compras!$D$6:$D$605,Compras!$B$6:$B$605,$A15,Compras!$C$6:$C$605,"Chico")>0,N($E15)<=$B$5),"C ","")&IF(AND(SUMIFS(Compras!$D$6:$D$605,Compras!$B$6:$B$605,$A15,Compras!$C$6:$C$605,"Mediano")>0,N($F15)<=$B$5),"M ","")&IF(AND(SUMIFS(Compras!$D$6:$D$605,Compras!$B$6:$B$605,$A15,Compras!$C$6:$C$605,"Grande")>0,N($G15)<=$B$5),"G","")),IF(N($H15)<=$B$5,"REPONER","")))) -> SIN STOCK | J15: =IF($A15="","",SUMIFS(Ventas!$D$6:$D$605,Ventas!$B$6:$B$605,$A15)) -> 1 | K15: =IF($A15="","",SUMIFS(Ventas!$F$6:$F$605,Ventas!$B$6:$B$605,$A15)) -> 12500
A16: =IF(Costos!$A30="","",Costos!$A30) -> Cubic Cuadrado | B16: =IF(Costos!$A30="","",Costos!$B30&"") -> Plata 925 | C16: =IF(Costos!$A30="","",Costos!$C30&"") -> Aros | D16: =IF($A16="","",SUMIFS(Compras!$D$6:$D$605,Compras!$B$6:$B$605,$A16,Compras!$C$6:$C$605,"Único")-SUMIFS(Ventas!$D$6:$D$605,Ventas!$B$6:$B$605,$A16,Ventas!$C$6:$C$605,"Único")) -> 0 | E16: =IF($A16="","",IF(LEFT($C16,6)="Anillo",SUMIFS(Compras!$D$6:$D$605,Compras!$B$6:$B$605,$A16,Compras!$C$6:$C$605,"Chico")-SUMIFS(Ventas!$D$6:$D$605,Ventas!$B$6:$B$605,$A16,Ventas!$C$6:$C$605,"Chico"),"")) | F16: =IF($A16="","",IF(LEFT($C16,6)="Anillo",SUMIFS(Compras!$D$6:$D$605,Compras!$B$6:$B$605,$A16,Compras!$C$6:$C$605,"Mediano")-SUMIFS(Ventas!$D$6:$D$605,Ventas!$B$6:$B$605,$A16,Ventas!$C$6:$C$605,"Mediano"),"")) | G16: =IF($A16="","",IF(LEFT($C16,6)="Anillo",SUMIFS(Compras!$D$6:$D$605,Compras!$B$6:$B$605,$A16,Compras!$C$6:$C$605,"Grande")-SUMIFS(Ventas!$D$6:$D$605,Ventas!$B$6:$B$605,$A16,Ventas!$C$6:$C$605,"Grande"),"")) | H16: =IF($A16="","",N($D16)+N($E16)+N($F16)+N($G16)) -> 0 | I16: =IF($A16="","",IF(N($H16)<=0,"SIN STOCK",IF(LEFT($C16,6)="Anillo",IF(IF(AND(SUMIFS(Compras!$D$6:$D$605,Compras!$B$6:$B$605,$A16,Compras!$C$6:$C$605,"Chico")>0,N($E16)<=$B$5),"C ","")&IF(AND(SUMIFS(Compras!$D$6:$D$605,Compras!$B$6:$B$605,$A16,Compras!$C$6:$C$605,"Mediano")>0,N($F16)<=$B$5),"M ","")&IF(AND(SUMIFS(Compras!$D$6:$D$605,Compras!$B$6:$B$605,$A16,Compras!$C$6:$C$605,"Grande")>0,N($G16)<=$B$5),"G","")="","","Reponer "&IF(AND(SUMIFS(Compras!$D$6:$D$605,Compras!$B$6:$B$605,$A16,Compras!$C$6:$C$605,"Chico")>0,N($E16)<=$B$5),"C ","")&IF(AND(SUMIFS(Compras!$D$6:$D$605,Compras!$B$6:$B$605,$A16,Compras!$C$6:$C$605,"Mediano")>0,N($F16)<=$B$5),"M ","")&IF(AND(SUMIFS(Compras!$D$6:$D$605,Compras!$B$6:$B$605,$A16,Compras!$C$6:$C$605,"Grande")>0,N($G16)<=$B$5),"G","")),IF(N($H16)<=$B$5,"REPONER","")))) -> SIN STOCK | J16: =IF($A16="","",SUMIFS(Ventas!$D$6:$D$605,Ventas!$B$6:$B$605,$A16)) -> 1 | K16: =IF($A16="","",SUMIFS(Ventas!$F$6:$F$605,Ventas!$B$6:$B$605,$A16)) -> 12500
A17: =IF(Costos!$A31="","",Costos!$A31) -> Argollitas Marco Docha | B17: =IF(Costos!$A31="","",Costos!$B31&"") -> Plata 925 | C17: =IF(Costos!$A31="","",Costos!$C31&"") -> Aros | D17: =IF($A17="","",SUMIFS(Compras!$D$6:$D$605,Compras!$B$6:$B$605,$A17,Compras!$C$6:$C$605,"Único")-SUMIFS(Ventas!$D$6:$D$605,Ventas!$B$6:$B$605,$A17,Ventas!$C$6:$C$605,"Único")) -> 0 | E17: =IF($A17="","",IF(LEFT($C17,6)="Anillo",SUMIFS(Compras!$D$6:$D$605,Compras!$B$6:$B$605,$A17,Compras!$C$6:$C$605,"Chico")-SUMIFS(Ventas!$D$6:$D$605,Ventas!$B$6:$B$605,$A17,Ventas!$C$6:$C$605,"Chico"),"")) | F17: =IF($A17="","",IF(LEFT($C17,6)="Anillo",SUMIFS(Compras!$D$6:$D$605,Compras!$B$6:$B$605,$A17,Compras!$C$6:$C$605,"Mediano")-SUMIFS(Ventas!$D$6:$D$605,Ventas!$B$6:$B$605,$A17,Ventas!$C$6:$C$605,"Mediano"),"")) | G17: =IF($A17="","",IF(LEFT($C17,6)="Anillo",SUMIFS(Compras!$D$6:$D$605,Compras!$B$6:$B$605,$A17,Compras!$C$6:$C$605,"Grande")-SUMIFS(Ventas!$D$6:$D$605,Ventas!$B$6:$B$605,$A17,Ventas!$C$6:$C$605,"Grande"),"")) | H17: =IF($A17="","",N($D17)+N($E17)+N($F17)+N($G17)) -> 0 | I17: =IF($A17="","",IF(N($H17)<=0,"SIN STOCK",IF(LEFT($C17,6)="Anillo",IF(IF(AND(SUMIFS(Compras!$D$6:$D$605,Compras!$B$6:$B$605,$A17,Compras!$C$6:$C$605,"Chico")>0,N($E17)<=$B$5),"C ","")&IF(AND(SUMIFS(Compras!$D$6:$D$605,Compras!$B$6:$B$605,$A17,Compras!$C$6:$C$605,"Mediano")>0,N($F17)<=$B$5),"M ","")&IF(AND(SUMIFS(Compras!$D$6:$D$605,Compras!$B$6:$B$605,$A17,Compras!$C$6:$C$605,"Grande")>0,N($G17)<=$B$5),"G","")="","","Reponer "&IF(AND(SUMIFS(Compras!$D$6:$D$605,Compras!$B$6:$B$605,$A17,Compras!$C$6:$C$605,"Chico")>0,N($E17)<=$B$5),"C ","")&IF(AND(SUMIFS(Compras!$D$6:$D$605,Compras!$B$6:$B$605,$A17,Compras!$C$6:$C$605,"Mediano")>0,N($F17)<=$B$5),"M ","")&IF(AND(SUMIFS(Compras!$D$6:$D$605,Compras!$B$6:$B$605,$A17,Compras!$C$6:$C$605,"Grande")>0,N($G17)<=$B$5),"G","")),IF(N($H17)<=$B$5,"REPONER","")))) -> SIN STOCK | J17: =IF($A17="","",SUMIFS(Ventas!$D$6:$D$605,Ventas!$B$6:$B$605,$A17)) -> 1 | K17: =IF($A17="","",SUMIFS(Ventas!$F$6:$F$605,Ventas!$B$6:$B$605,$A17)) -> 25000
A18: =IF(Costos!$A32="","",Costos!$A32) -> Anillo Circulo | B18: =IF(Costos!$A32="","",Costos!$B32&"") -> Plata 925 | C18: =IF(Costos!$A32="","",Costos!$C32&"") -> Anillo | D18: =IF($A18="","",SUMIFS(Compras!$D$6:$D$605,Compras!$B$6:$B$605,$A18,Compras!$C$6:$C$605,"Único")-SUMIFS(Ventas!$D$6:$D$605,Ventas!$B$6:$B$605,$A18,Ventas!$C$6:$C$605,"Único")) -> 0 | E18: =IF($A18="","",IF(LEFT($C18,6)="Anillo",SUMIFS(Compras!$D$6:$D$605,Compras!$B$6:$B$605,$A18,Compras!$C$6:$C$605,"Chico")-SUMIFS(Ventas!$D$6:$D$605,Ventas!$B$6:$B$605,$A18,Ventas!$C$6:$C$605,"Chico"),"")) -> 0 | F18: =IF($A18="","",IF(LEFT($C18,6)="Anillo",SUMIFS(Compras!$D$6:$D$605,Compras!$B$6:$B$605,$A18,Compras!$C$6:$C$605,"Mediano")-SUMIFS(Ventas!$D$6:$D$605,Ventas!$B$6:$B$605,$A18,Ventas!$C$6:$C$605,"Mediano"),"")) -> 0 | G18: =IF($A18="","",IF(LEFT($C18,6)="Anillo",SUMIFS(Compras!$D$6:$D$605,Compras!$B$6:$B$605,$A18,Compras!$C$6:$C$605,"Grande")-SUMIFS(Ventas!$D$6:$D$605,Ventas!$B$6:$B$605,$A18,Ventas!$C$6:$C$605,"Grande"),"")) -> 0 | H18: =IF($A18="","",N($D18)+N($E18)+N($F18)+N($G18)) -> 0 | I18: =IF($A18="","",IF(N($H18)<=0,"SIN STOCK",IF(LEFT($C18,6)="Anillo",IF(IF(AND(SUMIFS(Compras!$D$6:$D$605,Compras!$B$6:$B$605,$A18,Compras!$C$6:$C$605,"Chico")>0,N($E18)<=$B$5),"C ","")&IF(AND(SUMIFS(Compras!$D$6:$D$605,Compras!$B$6:$B$605,$A18,Compras!$C$6:$C$605,"Mediano")>0,N($F18)<=$B$5),"M ","")&IF(AND(SUMIFS(Compras!$D$6:$D$605,Compras!$B$6:$B$605,$A18,Compras!$C$6:$C$605,"Grande")>0,N($G18)<=$B$5),"G","")="","","Reponer "&IF(AND(SUMIFS(Compras!$D$6:$D$605,Compras!$B$6:$B$605,$A18,Compras!$C$6:$C$605,"Chico")>0,N($E18)<=$B$5),"C ","")&IF(AND(SUMIFS(Compras!$D$6:$D$605,Compras!$B$6:$B$605,$A18,Compras!$C$6:$C$605,"Mediano")>0,N($F18)<=$B$5),"M ","")&IF(AND(SUMIFS(Compras!$D$6:$D$605,Compras!$B$6:$B$605,$A18,Compras!$C$6:$C$605,"Grande")>0,N($G18)<=$B$5),"G","")),IF(N($H18)<=$B$5,"REPONER","")))) -> SIN STOCK | J18: =IF($A18="","",SUMIFS(Ventas!$D$6:$D$605,Ventas!$B$6:$B$605,$A18)) -> 2 | K18: =IF($A18="","",SUMIFS(Ventas!$F$6:$F$605,Ventas!$B$6:$B$605,$A18)) -> 32000
A19: =IF(Costos!$A33="","",Costos!$A33) -> Anillo Gota | B19: =IF(Costos!$A33="","",Costos!$B33&"") -> Plata 925 | C19: =IF(Costos!$A33="","",Costos!$C33&"") -> Anillo | D19: =IF($A19="","",SUMIFS(Compras!$D$6:$D$605,Compras!$B$6:$B$605,$A19,Compras!$C$6:$C$605,"Único")-SUMIFS(Ventas!$D$6:$D$605,Ventas!$B$6:$B$605,$A19,Ventas!$C$6:$C$605,"Único")) -> 0 | E19: =IF($A19="","",IF(LEFT($C19,6)="Anillo",SUMIFS(Compras!$D$6:$D$605,Compras!$B$6:$B$605,$A19,Compras!$C$6:$C$605,"Chico")-SUMIFS(Ventas!$D$6:$D$605,Ventas!$B$6:$B$605,$A19,Ventas!$C$6:$C$605,"Chico"),"")) -> 0 | F19: =IF($A19="","",IF(LEFT($C19,6)="Anillo",SUMIFS(Compras!$D$6:$D$605,Compras!$B$6:$B$605,$A19,Compras!$C$6:$C$605,"Mediano")-SUMIFS(Ventas!$D$6:$D$605,Ventas!$B$6:$B$605,$A19,Ventas!$C$6:$C$605,"Mediano"),"")) -> 0 | G19: =IF($A19="","",IF(LEFT($C19,6)="Anillo",SUMIFS(Compras!$D$6:$D$605,Compras!$B$6:$B$605,$A19,Compras!$C$6:$C$605,"Grande")-SUMIFS(Ventas!$D$6:$D$605,Ventas!$B$6:$B$605,$A19,Ventas!$C$6:$C$605,"Grande"),"")) -> 0 | H19: =IF($A19="","",N($D19)+N($E19)+N($F19)+N($G19)) -> 0 | I19: =IF($A19="","",IF(N($H19)<=0,"SIN STOCK",IF(LEFT($C19,6)="Anillo",IF(IF(AND(SUMIFS(Compras!$D$6:$D$605,Compras!$B$6:$B$605,$A19,Compras!$C$6:$C$605,"Chico")>0,N($E19)<=$B$5),"C ","")&IF(AND(SUMIFS(Compras!$D$6:$D$605,Compras!$B$6:$B$605,$A19,Compras!$C$6:$C$605,"Mediano")>0,N($F19)<=$B$5),"M ","")&IF(AND(SUMIFS(Compras!$D$6:$D$605,Compras!$B$6:$B$605,$A19,Compras!$C$6:$C$605,"Grande")>0,N($G19)<=$B$5),"G","")="","","Reponer "&IF(AND(SUMIFS(Compras!$D$6:$D$605,Compras!$B$6:$B$605,$A19,Compras!$C$6:$C$605,"Chico")>0,N($E19)<=$B$5),"C ","")&IF(AND(SUMIFS(Compras!$D$6:$D$605,Compras!$B$6:$B$605,$A19,Compras!$C$6:$C$605,"Mediano")>0,N($F19)<=$B$5),"M ","")&IF(AND(SUMIFS(Compras!$D$6:$D$605,Compras!$B$6:$B$605,$A19,Compras!$C$6:$C$605,"Grande")>0,N($G19)<=$B$5),"G","")),IF(N($H19)<=$B$5,"REPONER","")))) -> SIN STOCK | J19: =IF($A19="","",SUMIFS(Ventas!$D$6:$D$605,Ventas!$B$6:$B$605,$A19)) -> 1 | K19: =IF($A19="","",SUMIFS(Ventas!$F$6:$F$605,Ventas!$B$6:$B$605,$A19)) -> 23000
A20: =IF(Costos!$A34="","",Costos!$A34) -> Anillo Vera Docha | B20: =IF(Costos!$A34="","",Costos!$B34&"") -> Plata 925 | C20: =IF(Costos!$A34="","",Costos!$C34&"") -> Anillo | D20: =IF($A20="","",SUMIFS(Compras!$D$6:$D$605,Compras!$B$6:$B$605,$A20,Compras!$C$6:$C$605,"Único")-SUMIFS(Ventas!$D$6:$D$605,Ventas!$B$6:$B$605,$A20,Ventas!$C$6:$C$605,"Único")) -> 0 | E20: =IF($A20="","",IF(LEFT($C20,6)="Anillo",SUMIFS(Compras!$D$6:$D$605,Compras!$B$6:$B$605,$A20,Compras!$C$6:$C$605,"Chico")-SUMIFS(Ventas!$D$6:$D$605,Ventas!$B$6:$B$605,$A20,Ventas!$C$6:$C$605,"Chico"),"")) -> 0 | F20: =IF($A20="","",IF(LEFT($C20,6)="Anillo",SUMIFS(Compras!$D$6:$D$605,Compras!$B$6:$B$605,$A20,Compras!$C$6:$C$605,"Mediano")-SUMIFS(Ventas!$D$6:$D$605,Ventas!$B$6:$B$605,$A20,Ventas!$C$6:$C$605,"Mediano"),"")) -> 0 | G20: =IF($A20="","",IF(LEFT($C20,6)="Anillo",SUMIFS(Compras!$D$6:$D$605,Compras!$B$6:$B$605,$A20,Compras!$C$6:$C$605,"Grande")-SUMIFS(Ventas!$D$6:$D$605,Ventas!$B$6:$B$605,$A20,Ventas!$C$6:$C$605,"Grande"),"")) -> 1 | H20: =IF($A20="","",N($D20)+N($E20)+N($F20)+N($G20)) -> 1 | I20: =IF($A20="","",IF(N($H20)<=0,"SIN STOCK",IF(LEFT($C20,6)="Anillo",IF(IF(AND(SUMIFS(Compras!$D$6:$D$605,Compras!$B$6:$B$605,$A20,Compras!$C$6:$C$605,"Chico")>0,N($E20)<=$B$5),"C ","")&IF(AND(SUMIFS(Compras!$D$6:$D$605,Compras!$B$6:$B$605,$A20,Compras!$C$6:$C$605,"Mediano")>0,N($F20)<=$B$5),"M ","")&IF(AND(SUMIFS(Compras!$D$6:$D$605,Compras!$B$6:$B$605,$A20,Compras!$C$6:$C$605,"Grande")>0,N($G20)<=$B$5),"G","")="","","Reponer "&IF(AND(SUMIFS(Compras!$D$6:$D$605,Compras!$B$6:$B$605,$A20,Compras!$C$6:$C$605,"Chico")>0,N($E20)<=$B$5),"C ","")&IF(AND(SUMIFS(Compras!$D$6:$D$605,Compras!$B$6:$B$605,$A20,Compras!$C$6:$C$605,"Mediano")>0,N($F20)<=$B$5),"M ","")&IF(AND(SUMIFS(Compras!$D$6:$D$605,Compras!$B$6:$B$605,$A20,Compras!$C$6:$C$605,"Grande")>0,N($G20)<=$B$5),"G","")),IF(N($H20)<=$B$5,"REPONER","")))) -> Reponer G | J20: =IF($A20="","",SUMIFS(Ventas!$D$6:$D$605,Ventas!$B$6:$B$605,$A20)) -> 0 | K20: =IF($A20="","",SUMIFS(Ventas!$F$6:$F$605,Ventas!$B$6:$B$605,$A20)) -> 0
... A136: =IF(Costos!$A150="","",Costos!$A150) | B136: =IF(Costos!$A150="","",Costos!$B150&"") | C136: =IF(Costos!$A150="","",Costos!$C150&"") | D136: =IF($A136="","",SUMIFS(Compras!$D$6:$D$605,Compras!$B$6:$B$605,$A136,Compras!$C$6:$C$605,"Único")-SUMIFS(Ventas!$D$6:$D$605,Ventas!$B$6:$B$605,$A136,Ventas!$C$6:$C$605,"Único")) | E136: =IF($A136="","",IF(LEFT($C136,6)="Anillo",SUMIFS(Compras!$D$6:$D$605,Compras!$B$6:$B$605,$A136,Compras!$C$6:$C$605,"Chico")-SUMIFS(Ventas!$D$6:$D$605,Ventas!$B$6:$B$605,$A136,Ventas!$C$6:$C$605,"Chico"),"")) | F136: =IF($A136="","",IF(LEFT($C136,6)="Anillo",SUMIFS(Compras!$D$6:$D$605,Compras!$B$6:$B$605,$A136,Compras!$C$6:$C$605,"Mediano")-SUMIFS(Ventas!$D$6:$D$605,Ventas!$B$6:$B$605,$A136,Ventas!$C$6:$C$605,"Mediano"),"")) | G136: =IF($A136="","",IF(LEFT($C136,6)="Anillo",SUMIFS(Compras!$D$6:$D$605,Compras!$B$6:$B$605,$A136,Compras!$C$6:$C$605,"Grande")-SUMIFS(Ventas!$D$6:$D$605,Ventas!$B$6:$B$605,$A136,Ventas!$C$6:$C$605,"Grande"),"")) | H136: =IF($A136="","",N($D136)+N($E136)+N($F136)+N($G136)) | I136: =IF($A136="","",IF(N($H136)<=0,"SIN STOCK",IF(LEFT($C136,6)="Anillo",IF(IF(AND(SUMIFS(Compras!$D$6:$D$605,Compras!$B$6:$B$605,$A136,Compras!$C$6:$C$605,"Chico")>0,N($E136)<=$B$5),"C ","")&IF(AND(SUMIFS(Compras!$D$6:$D$605,Compras!$B$6:$B$605,$A136,Compras!$C$6:$C$605,"Mediano")>0,N($F136)<=$B$5),"M ","")&IF(AND(SUMIFS(Compras!$D$6:$D$605,Compras!$B$6:$B$605,$A136,Compras!$C$6:$C$605,"Grande")>0,N($G136)<=$B$5),"G","")="","","Reponer "&IF(AND(SUMIFS(Compras!$D$6:$D$605,Compras!$B$6:$B$605,$A136,Compras!$C$6:$C$605,"Chico")>0,N($E136)<=$B$5),"C ","")&IF(AND(SUMIFS(Compras!$D$6:$D$605,Compras!$B$6:$B$605,$A136,Compras!$C$6:$C$605,"Mediano")>0,N($F136)<=$B$5),"M ","")&IF(AND(SUMIFS(Compras!$D$6:$D$605,Compras!$B$6:$B$605,$A136,Compras!$C$6:$C$605,"Grande")>0,N($G136)<=$B$5),"G","")),IF(N($H136)<=$B$5,"REPONER","")))) | J136: =IF($A136="","",SUMIFS(Ventas!$D$6:$D$605,Ventas!$B$6:$B$605,$A136)) | K136: =IF($A136="","",SUMIFS(Ventas!$F$6:$F$605,Ventas!$B$6:$B$605,$A136))
A145: Cómo leer esta hoja
A146: • Todo sale de Compras y Ventas. La única celda editable acá es el aviso de B5.
A147: • Estado dice SIN STOCK cuando no queda nada y REPONER cuando quedan pocas.
A148: • En anillos, Reponer nombra solo los talles que alguna vez compraste.

Sheet Web
A1: DATOS PARA LA WEB
A2: Esta hoja se completa sola desde Costos y Stock. No cargues nada acá salvo la columna Destacado y la de Foto.
A3: Es la única hoja que se publica: no incluye costos, proveedores ni márgenes.
A5: Producto | B5: Material | C5: Categoría | D5: Precio | E5: Stock | F5: Chico | G5: Mediano | H5: Grande | I5: Destacado | J5: Foto (link) | K5: Vendidas
A6: =IF(Costos!$A23="","",Costos!$A23) -> Argollitas Classic N°1 | B6: =IF(Costos!$A23="","",Costos!$B23&"") -> Plata 925 | C6: =IF(Costos!$A23="","",Costos!$C23&"") -> Aros | D6: =IF(Costos!$A23="","",N(Costos!$K23)) -> 7000 | E6: =IF(Costos!$A23="","",N(Stock!$H9)) -> 0 | F6: =IF(Costos!$A23="","",N(Stock!$E9)+IF(LEFT(Stock!$C9,6)="Anillo",0,N(Stock!$D9))) -> 0 | G6: =IF(Costos!$A23="","",N(Stock!$F9)) -> 0 | H6: =IF(Costos!$A23="","",N(Stock!$G9)) -> 0 | K6: =IF(Costos!$A23="","",N(Stock!$J9)) -> 1
A7: =IF(Costos!$A24="","",Costos!$A24) -> Argollitas Classic N°2 | B7: =IF(Costos!$A24="","",Costos!$B24&"") -> Plata 925 | C7: =IF(Costos!$A24="","",Costos!$C24&"") -> Aros | D7: =IF(Costos!$A24="","",N(Costos!$K24)) -> 7500 | E7: =IF(Costos!$A24="","",N(Stock!$H10)) -> 0 | F7: =IF(Costos!$A24="","",N(Stock!$E10)+IF(LEFT(Stock!$C10,6)="Anillo",0,N(Stock!$D10))) -> 0 | G7: =IF(Costos!$A24="","",N(Stock!$F10)) -> 0 | H7: =IF(Costos!$A24="","",N(Stock!$G10)) -> 0 | K7: =IF(Costos!$A24="","",N(Stock!$J10)) -> 1
A8: =IF(Costos!$A25="","",Costos!$A25) -> Argollitas Classic N°3 | B8: =IF(Costos!$A25="","",Costos!$B25&"") -> Plata 925 | C8: =IF(Costos!$A25="","",Costos!$C25&"") -> Aros | D8: =IF(Costos!$A25="","",N(Costos!$K25)) -> 8000 | E8: =IF(Costos!$A25="","",N(Stock!$H11)) -> 0 | F8: =IF(Costos!$A25="","",N(Stock!$E11)+IF(LEFT(Stock!$C11,6)="Anillo",0,N(Stock!$D11))) -> 0 | G8: =IF(Costos!$A25="","",N(Stock!$F11)) -> 0 | H8: =IF(Costos!$A25="","",N(Stock!$G11)) -> 0 | K8: =IF(Costos!$A25="","",N(Stock!$J11)) -> 1
A9: =IF(Costos!$A26="","",Costos!$A26) -> Argollitas Classic N°4 | B9: =IF(Costos!$A26="","",Costos!$B26&"") -> Plata 925 | C9: =IF(Costos!$A26="","",Costos!$C26&"") -> Aros | D9: =IF(Costos!$A26="","",N(Costos!$K26)) -> 8500 | E9: =IF(Costos!$A26="","",N(Stock!$H12)) -> 0 | F9: =IF(Costos!$A26="","",N(Stock!$E12)+IF(LEFT(Stock!$C12,6)="Anillo",0,N(Stock!$D12))) -> 0 | G9: =IF(Costos!$A26="","",N(Stock!$F12)) -> 0 | H9: =IF(Costos!$A26="","",N(Stock!$G12)) -> 0 | K9: =IF(Costos!$A26="","",N(Stock!$J12)) -> 1
A10: =IF(Costos!$A27="","",Costos!$A27) -> Argollitas Classic N°5 | B10: =IF(Costos!$A27="","",Costos!$B27&"") -> Plata 925 | C10: =IF(Costos!$A27="","",Costos!$C27&"") -> Aros | D10: =IF(Costos!$A27="","",N(Costos!$K27)) -> 9000 | E10: =IF(Costos!$A27="","",N(Stock!$H13)) -> 1 | F10: =IF(Costos!$A27="","",N(Stock!$E13)+IF(LEFT(Stock!$C13,6)="Anillo",0,N(Stock!$D13))) -> 1 | G10: =IF(Costos!$A27="","",N(Stock!$F13)) -> 0 | H10: =IF(Costos!$A27="","",N(Stock!$G13)) -> 0 | K10: =IF(Costos!$A27="","",N(Stock!$J13)) -> 1
A11: =IF(Costos!$A28="","",Costos!$A28) -> Cubic Mini Circulo | B11: =IF(Costos!$A28="","",Costos!$B28&"") -> Plata 925 | C11: =IF(Costos!$A28="","",Costos!$C28&"") -> Aros | D11: =IF(Costos!$A28="","",N(Costos!$K28)) -> 12000 | E11: =IF(Costos!$A28="","",N(Stock!$H14)) -> 0 | F11: =IF(Costos!$A28="","",N(Stock!$E14)+IF(LEFT(Stock!$C14,6)="Anillo",0,N(Stock!$D14))) -> 0 | G11: =IF(Costos!$A28="","",N(Stock!$F14)) -> 0 | H11: =IF(Costos!$A28="","",N(Stock!$G14)) -> 0 | K11: =IF(Costos!$A28="","",N(Stock!$J14)) -> 1
A12: =IF(Costos!$A29="","",Costos!$A29) -> Cubic Circulo Docha | B12: =IF(Costos!$A29="","",Costos!$B29&"") -> Plata 925 | C12: =IF(Costos!$A29="","",Costos!$C29&"") -> Aros | D12: =IF(Costos!$A29="","",N(Costos!$K29)) -> 12500 | E12: =IF(Costos!$A29="","",N(Stock!$H15)) -> 0 | F12: =IF(Costos!$A29="","",N(Stock!$E15)+IF(LEFT(Stock!$C15,6)="Anillo",0,N(Stock!$D15))) -> 0 | G12: =IF(Costos!$A29="","",N(Stock!$F15)) -> 0 | H12: =IF(Costos!$A29="","",N(Stock!$G15)) -> 0 | K12: =IF(Costos!$A29="","",N(Stock!$J15)) -> 1
A13: =IF(Costos!$A30="","",Costos!$A30) -> Cubic Cuadrado | B13: =IF(Costos!$A30="","",Costos!$B30&"") -> Plata 925 | C13: =IF(Costos!$A30="","",Costos!$C30&"") -> Aros | D13: =IF(Costos!$A30="","",N(Costos!$K30)) -> 12500 | E13: =IF(Costos!$A30="","",N(Stock!$H16)) -> 0 | F13: =IF(Costos!$A30="","",N(Stock!$E16)+IF(LEFT(Stock!$C16,6)="Anillo",0,N(Stock!$D16))) -> 0 | G13: =IF(Costos!$A30="","",N(Stock!$F16)) -> 0 | H13: =IF(Costos!$A30="","",N(Stock!$G16)) -> 0 | K13: =IF(Costos!$A30="","",N(Stock!$J16)) -> 1
A14: =IF(Costos!$A31="","",Costos!$A31) -> Argollitas Marco Docha | B14: =IF(Costos!$A31="","",Costos!$B31&"") -> Plata 925 | C14: =IF(Costos!$A31="","",Costos!$C31&"") -> Aros | D14: =IF(Costos!$A31="","",N(Costos!$K31)) -> 25000 | E14: =IF(Costos!$A31="","",N(Stock!$H17)) -> 0 | F14: =IF(Costos!$A31="","",N(Stock!$E17)+IF(LEFT(Stock!$C17,6)="Anillo",0,N(Stock!$D17))) -> 0 | G14: =IF(Costos!$A31="","",N(Stock!$F17)) -> 0 | H14: =IF(Costos!$A31="","",N(Stock!$G17)) -> 0 | K14: =IF(Costos!$A31="","",N(Stock!$J17)) -> 1
